[2024-01-30T23:24:09.855+0100] {taskinstance.py:1957} INFO - Dependencies all met for dep_context=non-requeueable deps ti=<TaskInstance: meteo.python_task manual__2024-01-30T22:23:40.100258+00:00 [queued]>
[2024-01-30T23:24:09.891+0100] {taskinstance.py:1957} INFO - Dependencies all met for dep_context=requeueable deps ti=<TaskInstance: meteo.python_task manual__2024-01-30T22:23:40.100258+00:00 [queued]>
[2024-01-30T23:24:09.896+0100] {taskinstance.py:2171} INFO - Starting attempt 1 of 2
[2024-01-30T23:24:10.300+0100] {taskinstance.py:2192} INFO - Executing <Task(PythonOperator): python_task> on 2024-01-30 22:23:40.100258+00:00
[2024-01-30T23:24:10.390+0100] {standard_task_runner.py:60} INFO - Started process 7886 to run task
[2024-01-30T23:24:10.409+0100] {standard_task_runner.py:87} INFO - Running: ['airflow', 'tasks', 'run', 'meteo', 'python_task', 'manual__2024-01-30T22:23:40.100258+00:00', '--job-id', '21', '--raw', '--subdir', 'DAGS_FOLDER/meteo.py', '--cfg-path', '/tmp/tmp1bxhctn8']
[2024-01-30T23:24:10.417+0100] {standard_task_runner.py:88} INFO - Job 21: Subtask python_task
[2024-01-30T23:24:11.024+0100] {task_command.py:423} INFO - Running <TaskInstance: meteo.python_task manual__2024-01-30T22:23:40.100258+00:00 [running]> on host ubuntu.ubuntu.virtualbox.org
[2024-01-30T23:24:12.007+0100] {taskinstance.py:2481} INFO - Exporting env vars: AIRFLOW_CTX_DAG_OWNER='airflow' AIRFLOW_CTX_DAG_ID='meteo' AIRFLOW_CTX_TASK_ID='python_task' AIRFLOW_CTX_EXECUTION_DATE='2024-01-30T22:23:40.100258+00:00' AIRFLOW_CTX_TRY_NUMBER='1' AIRFLOW_CTX_DAG_RUN_ID='manual__2024-01-30T22:23:40.100258+00:00'
[2024-01-30T23:24:12.832+0100] {client.py:192} INFO - Instantiated <InsecureClient(url='http://localhost:9870')>.
[2024-01-30T23:24:12.837+0100] {client.py:496} INFO - Writing to '/user/Datalake/raw/temperature/2024-01-30.json'.
[2024-01-30T23:24:13.066+0100] {util.py:78} ERROR - Exception in child.
Traceback (most recent call last):
  File "/home/ubuntu/.local/lib/python3.10/site-packages/hdfs/util.py", line 76, in consumer
    self._consumer(data)
  File "/home/ubuntu/.local/lib/python3.10/site-packages/hdfs/client.py", line 515, in consumer
    raise _to_error(res)
hdfs.util.HdfsError: /user/Datalake/raw/temperature/2024-01-30.json for client 127.0.0.1 already exists
	at org.apache.hadoop.hdfs.server.namenode.FSDirWriteFileOp.startFile(FSDirWriteFileOp.java:389)
	at org.apache.hadoop.hdfs.server.namenode.FSNamesystem.startFileInt(FSNamesystem.java:2732)
	at org.apache.hadoop.hdfs.server.namenode.FSNamesystem.startFile(FSNamesystem.java:2625)
	at org.apache.hadoop.hdfs.server.namenode.NameNodeRpcServer.create(NameNodeRpcServer.java:807)
	at org.apache.hadoop.hdfs.protocolPB.ClientNamenodeProtocolServerSideTranslatorPB.create(ClientNamenodeProtocolServerSideTranslatorPB.java:496)
	at org.apache.hadoop.hdfs.protocol.proto.ClientNamenodeProtocolProtos$ClientNamenodeProtocol$2.callBlockingMethod(ClientNamenodeProtocolProtos.java)
	at org.apache.hadoop.ipc.ProtobufRpcEngine2$Server$ProtoBufRpcInvoker.call(ProtobufRpcEngine2.java:621)
	at org.apache.hadoop.ipc.ProtobufRpcEngine2$Server$ProtoBufRpcInvoker.call(ProtobufRpcEngine2.java:589)
	at org.apache.hadoop.ipc.ProtobufRpcEngine2$Server$ProtoBufRpcInvoker.call(ProtobufRpcEngine2.java:573)
	at org.apache.hadoop.ipc.RPC$Server.call(RPC.java:1227)
	at org.apache.hadoop.ipc.Server$RpcCall.run(Server.java:1094)
	at org.apache.hadoop.ipc.Server$RpcCall.run(Server.java:1017)
	at java.security.AccessController.doPrivileged(Native Method)
	at javax.security.auth.Subject.doAs(Subject.java:422)
	at org.apache.hadoop.security.UserGroupInformation.doAs(UserGroupInformation.java:1899)
	at org.apache.hadoop.ipc.Server$Handler.run(Server.java:3048)

[2024-01-30T23:24:13.075+0100] {logging_mixin.py:188} INFO - Une erreur s'est produite : /user/Datalake/raw/temperature/2024-01-30.json for client 127.0.0.1 already exists
	at org.apache.hadoop.hdfs.server.namenode.FSDirWriteFileOp.startFile(FSDirWriteFileOp.java:389)
	at org.apache.hadoop.hdfs.server.namenode.FSNamesystem.startFileInt(FSNamesystem.java:2732)
	at org.apache.hadoop.hdfs.server.namenode.FSNamesystem.startFile(FSNamesystem.java:2625)
	at org.apache.hadoop.hdfs.server.namenode.NameNodeRpcServer.create(NameNodeRpcServer.java:807)
	at org.apache.hadoop.hdfs.protocolPB.ClientNamenodeProtocolServerSideTranslatorPB.create(ClientNamenodeProtocolServerSideTranslatorPB.java:496)
	at org.apache.hadoop.hdfs.protocol.proto.ClientNamenodeProtocolProtos$ClientNamenodeProtocol$2.callBlockingMethod(ClientNamenodeProtocolProtos.java)
	at org.apache.hadoop.ipc.ProtobufRpcEngine2$Server$ProtoBufRpcInvoker.call(ProtobufRpcEngine2.java:621)
	at org.apache.hadoop.ipc.ProtobufRpcEngine2$Server$ProtoBufRpcInvoker.call(ProtobufRpcEngine2.java:589)
	at org.apache.hadoop.ipc.ProtobufRpcEngine2$Server$ProtoBufRpcInvoker.call(ProtobufRpcEngine2.java:573)
	at org.apache.hadoop.ipc.RPC$Server.call(RPC.java:1227)
	at org.apache.hadoop.ipc.Server$RpcCall.run(Server.java:1094)
	at org.apache.hadoop.ipc.Server$RpcCall.run(Server.java:1017)
	at java.security.AccessController.doPrivileged(Native Method)
	at javax.security.auth.Subject.doAs(Subject.java:422)
	at org.apache.hadoop.security.UserGroupInformation.doAs(UserGroupInformation.java:1899)
	at org.apache.hadoop.ipc.Server$Handler.run(Server.java:3048)
[2024-01-30T23:24:13.075+0100] {python.py:201} INFO - Done. Returned value was: None
[2024-01-30T23:24:13.119+0100] {taskinstance.py:1138} INFO - Marking task as SUCCESS. dag_id=meteo, task_id=python_task, execution_date=20240130T222340, start_date=20240130T222409, end_date=20240130T222413
[2024-01-30T23:24:13.615+0100] {local_task_job_runner.py:234} INFO - Task exited with return code 0
[2024-01-30T23:24:13.669+0100] {taskinstance.py:3281} INFO - 0 downstream tasks scheduled from follow-on schedule check
